<robot name="minimal_two_link_robot">
  <link name="link1">
    <visual>
      <geometry>
        <box size="0.2 0.1 0.1"/>
      </geometry>
      <origin xyz=".1 0 0" rpy="0 0 0"/>
    </visual>
  </link>
  <link name="link2">
    <visual>
      <geometry>
        <box size="0.2 0.1 0.1"/>
      </geometry>
      <origin xyz=".1 0 -0.05" rpy="0 0 0"/>
    </visual>
  </link>
  <joint name="joint1" type="revolute">
    <parent link="link1"/>
    <child link="link2"/>
    <origin xyz="0.2 0 0.05" rpy="0 0 0"/>
    <axis xyz="0 1 0"/>
    <limit lower="-1.57" upper="1.57" effort="1" velocity="1"/>
  </joint>
</robot> 