<robot name="my_robot">

  <link name="STS3125">
    <inertial>
      <origin xyz="0.000000 -0.000161 0.011957" rpy="0 0 0"/>
      <mass value="0.044802"/>
      <inertia ixx="0.011811" ixy="0.000000" ixz="0.000000" iyy="0.009677" iyz="-0.000086" izz="0.006346" />
    </inertial>
    <visual>
      <origin xyz="0 0 0" rpy="0 0 0"/>
      <geometry>
        <mesh filename="package://my_robot/meshes/STS3125.stl"/>
      </geometry>
    </visual>
    <collision>
      <origin xyz="0 0 0" rpy="0 0 0"/>
      <geometry>
        <mesh filename="package://my_robot/meshes/STS3125.stl"/>
      </geometry>
    </collision>
  </link>
  <link name="Servo_Case_to_Grid">
    <inertial>
      <origin xyz="0.000000 0.000323 0.015498" rpy="0 0 0"/>
      <mass value="0.022553"/>
      <inertia ixx="0.012953" ixy="-0.000000" ixz="-0.000000" iyy="0.013403" iyz="0.000023" izz="0.005267" />
    </inertial>
    <visual>
      <origin xyz="0 0 0" rpy="0 0 0"/>
      <geometry>
        <mesh filename="package://my_robot/meshes/Servo_Case_to_Grid.stl"/>
      </geometry>
    </visual>
    <collision>
      <origin xyz="0 0 0" rpy="0 0 0"/>
      <geometry>
        <mesh filename="package://my_robot/meshes/Servo_Case_to_Grid.stl"/>
      </geometry>
    </collision>
  </link>
  <link name="Foot_V2">
    <inertial>
      <origin xyz="0.009189 -0.000000 -0.022831" rpy="0 0 0"/>
      <mass value="0.074616"/>
      <inertia ixx="0.030522" ixy="-0.000000" ixz="0.002608" iyy="0.089712" iyz="0.000000" izz="0.105091" />
    </inertial>
    <visual>
      <origin xyz="0 0 0" rpy="0 0 0"/>
      <geometry>
        <mesh filename="package://my_robot/meshes/Foot_V2.stl"/>
      </geometry>
    </visual>
    <collision>
      <origin xyz="0 0 0" rpy="0 0 0"/>
      <geometry>
        <mesh filename="package://my_robot/meshes/Foot_V2.stl"/>
      </geometry>
    </collision>
  </link>
  <joint name="world_to_Foot_V2" type="fixed">
    <parent link="world"/>
    <child link="Foot_V2"/>
    <origin xyz="0 0 0" rpy="0 0 0"/>
  </joint>
  <joint name="STS3125_to_Foot_V2" type="revolute">
    <parent link="STS3125"/>
    <child link="Foot_V2"/>
    <origin xyz="-0.000000 0.018000 -0.000000" rpy="0.000000 -0.000000 -1.570796"/>
    <axis xyz="0 0 1"/>
  </joint>
  <joint name="Servo_Case_to_Grid_to_STS3125" type="fixed">
    <parent link="Servo_Case_to_Grid"/>
    <child link="STS3125"/>
    <origin xyz="-0.000000 0.016000 -0.000000" rpy="0.000000 -1.570796 3.141593"/>
  </joint>
</robot>
